<?xml version="1.0"?>
<robot name="ROCO_ROBOT_ARM">

 

  <material name="blue">
   <color rgba="0 0 1 1"/>
  </material>

 

  <material name="white">
    <color rgba="1 1 1 1"/>
  </material>



  <material name="green">
    <color rgba="0.2 0.6 0.3 1"/>
  </material>

 

  <material name="red">
    <color rgba="1 0 0 1"/>
  </material>

<link name="C4">
    <visual>
      <geometry>       
        	
         <mesh filename="file:///home/student/ROCO222_ROS/Robot_project/models/STL_files/forearm-middle.stl" scale="0.01 0.01 0.01" />
      </geometry>
        <origin rpy="1.57 1.57 1.57" xyz="-0.1 -0.025 -0.15" />  
         <material name="green"/>
   </visual>
  </link>

<link name="C3">
    <visual>
      <geometry>       
        	
         <mesh filename="file:///home/student/ROCO222_ROS/Robot_project/models/STL_files/forearm-middle3.stl" scale="0.01 0.01 0.01" />
      </geometry>
        <origin rpy="1.57 1.57 1.57" xyz="-0.1 -1.5 -0.15" />  
         <material name="green"/>
   </visual>
  </link>

<!-- <link name="BASE_LOWER">
    <visual>
      <geometry>       
        	
         <mesh filename="file:///home/student/ROCO222_ROS/Robot_project/models/STL_files/Stepperother.stl" scale="0.01 0.01 0.01" />
      </geometry>
        <origin rpy="1.57 1.57 1.57" xyz="-0.1 -1.5 -0.15" />  
         <material name="green"/>
   </visual>
  </link>

<link name="BASE_UPPER">
    <visual>
      <geometry>       
        	
           <mesh filename="file:///home/student/ROCO222_ROS/Robot_project/models/STL_files/Stepper2.stl" scale="0.01 0.01 0.01" />
      </geometry>
        <origin rpy="1.57 1.57 1.57" xyz="-0.1 -1.5 -0.15" />  
         <material name="green"/>
   </visual>
  </link> -->

<link name="C2">
    <visual>
      <geometry>       
        	
         <mesh filename="file:///home/student/ROCO222_ROS/Robot_project/models/STL_files/BackArm-Middleconnector-01.stl" scale="0.01 0.01 0.01" />
      </geometry>
        <origin rpy="1.57 1.57 1.57" xyz="-0.1 -1.90 -0.19" />  
         <material name="green"/>
   </visual>
  </link>

<link name="C1">
    <visual>
      <geometry>       
        	
         <mesh filename="file:///home/student/ROCO222_ROS/Robot_project/models/STL_files/BackArm-Middleconnector2.stl" scale="0.01 0.01 0.01" />
      </geometry>
        <origin rpy="1.57 1.57 1.57" xyz="-0.1 -3.3 -0.19" />  
         <material name="green"/>
   </visual>
  </link>

<link name="FOREARM_R">
    <visual>
      <geometry>       
         	
         <mesh filename="file:///home/student/ROCO222_ROS/Robot_project/models/STL_files/forearm-sides-01.STL" scale="0.01 0.01 0.01" />
      </geometry>
        <origin rpy="1.57 1.57 1.57" xyz="0.2 -1.48 0.15" />  
         <material name="green"/>
   </visual>
  </link>

<link name="FOREARM_L">
    <visual>
      <geometry>       
        	
         <mesh filename="file:///home/student/ROCO222_ROS/Robot_project/models/STL_files/forearm-sides-02.stl" scale="0.01 0.01 0.01" />
      </geometry>
        <origin rpy="1.57 1.57 1.57" xyz="0.2 -1.48 -0.25" />  
         <material name="green"/>
   </visual>
  </link>

<link name="LOWERARM_L">
    <visual>
      <geometry>       
        	
         <mesh filename="file:///home/student/ROCO222_ROS/Robot_project/models/STL_files/backarm-sides-01.stl" scale="0.01 0.01 0.01" />
      </geometry>
        <origin rpy="1.57 1.57 1.57" xyz="0.2 -3.28 -0.19" />  
         <material name="green"/>
   </visual>
  </link>

<link name="LOWERARM_R">
    <visual>
      <geometry>       
        	
         <mesh filename="file:///home/student/ROCO222_ROS/Robot_project/models/STL_files/backarm-sides-02.stl" scale="0.01 0.01 0.01" />
      </geometry>
        <origin rpy="1.57 1.57 1.57" xyz="0.2 -3.28 0.09" />  
         <material name="green"/>
   </visual>
  </link>

  <link name="Hand_back">
    <visual>
      <geometry>       
       	
         <mesh filename="file:///home/student/ROCO222_ROS/Robot_project/models/STL_files/Handy.STL" scale="0.01 0.01 0.01" />
   
      </geometry>
    
         <origin rpy="0 1.57 0" xyz="0.0 0.625 -0.1" />
    
         <material name="blue"/>
  
   </visual>
 
  </link>

 

  <link name="Hand_front">
 
    <visual>
      
      <geometry>
        
        <!-- box size="0.040 0.005 0.125"/> -->
	
        <mesh filename="file:///home/student/ROCO222_ROS/Robot_project/models/STL_files/Hand_Top.STL" scale="0.01 0.01 0.01" />
  
      </geometry>
      
        <origin rpy="0 1.57 0" xyz="0.0750 0.06 0" />
   
        <material name="white"/>
   
    </visual>
    
  </link>



<link name="Hand_finger">
	<visual><geometry>

	<mesh filename="file:///home/student/ROCO222_ROS/Robot_project/models/STL_files/Finger.STL" scale="0.01 0.01 0.01"/>
	</geometry>
	<origin rpy="0 1.57 0" xyz="0.015 0.525 -0.1"/>
	<material name="red"/>
	</visual>
</link>



  <joint name="Hand_FB" type="fixed">
    

     <parent link="Hand_back"/>
    
     <child link="Hand_front"/>
 
     <origin xyz="0 0 0" />
  
  </joint>

  <joint name="C4_Hand" type="fixed">
    

     <parent link="C4"/>
    
     <child link="Hand_back"/>
 
     <origin xyz="0 0 0" />
  
  </joint>

  <joint name="C2_Arm" type="fixed">
    

     <parent link="C4"/>
    
     <child link="C2"/>
 
     <origin xyz="0 0 0" />
  
  </joint>

  <joint name="C1_Arm" type="fixed">
    

     <parent link="C4"/>
    
     <child link="C1"/>
 
     <origin xyz="0 0 0" />
  
  </joint>

  <joint name="C3_ARMR" type="fixed">
    

     <parent link="FOREARM_R"/>
    
     <child link="C3"/>
 
     <origin xyz="0 0 0" />
  
  </joint>

  <joint name="C3_ARML" type="fixed">
    

     <parent link="FOREARM_L"/>
    
     <child link="C3"/>
 
     <origin xyz="0 0 0" />
  
  </joint>

 <!-- <joint name="BASEL" type="fixed">
     <parent link="BASE_UPPER"/>
    
     <child link="BASE_LOWER"/>
 
     <origin xyz="0 0 0" />
  
  </joint>

 <joint name="BASEA" type="fixed">
    

     <parent link="BASE_UPPER"/>
    
     <child link="LOWERARM_R"/>
 
     <origin xyz="0 0 0" />
  
  </joint> -->


  <joint name="ARML" type="revolute">
    
	<axis xyz="0 -1 0" />
 
     <limit effort="1000" lower="-3.14" upper="3.14" velocity="0.5" />
 
     <parent link="C4"/>
    
     <child link="LOWERARM_L"/>
 
     <origin xyz="0 0 0" />
  
  </joint>


  <joint name="ARMR" type="fixed">
    
<axis xyz="0 -1 0" />
 
     <limit effort="1000" lower="-3.14" upper="3.14" velocity="0.5" />
 
     <parent link="C4"/>
    
     <child link="LOWERARM_R"/>
 
     <origin xyz="0 0 0" />
  
  </joint>


  <joint name="C4_R" type="fixed">
    

     <parent link="C4"/>
    
     <child link="FOREARM_R"/>
 
     <origin xyz="0 0 0" />
  
  </joint>
 
  <joint name="C4_L" type="fixed">
    

     <parent link="C4"/>
    
     <child link="FOREARM_L"/>
 
     <origin xyz="0 0 0" />
  
  </joint>

  <joint name="Finger" type="revolute">
 
     <axis xyz="0 -1 0" />
 
     <limit effort="1000" lower="-3.14" upper="3.14" velocity="0.5" />
 
    <parent link="Hand_back"/>
 
     <child link="Hand_finger"/>
  
     <origin xyz="0.0 0 0" />
 
  </joint>



</robot>





