<?xml version="1.0"?>

<robot name="ROCO_ROBOT_ARM">

 

  <material name="blue">
 
    <color rgba="0 0 1 1"/>
 
  </material>

 

  <material name="white">
  
    <color rgba="1 1 1 1"/>
 
  </material>



  <material name="green">
 
    <color rgba="0.2 0.6 0.3 1"/>
 
  </material>

 

  <material name="red">
 
    <color rgba="1 0 0 1"/>
 
  </material>



  <link name="Hand_back">
 
    <visual>
      
      <geometry>
        
         <!-- box size="0.040 0.005 0.125"/> -->
	
         <mesh filename="file:///home/student/ROCO222_ROS/Robot_project/models/STL_files/Hand_back_part.STL" scale="0.01 0.01 0.01" />
   
      </geometry>
    
         <origin rpy="0 1.57 0" xyz="0 0 0" />
    
         <material name="blue"/>
  
   </visual>
 
  </link>

 

  <link name="Hand_front">
 
    <visual>
      
      <geometry>
        
        <!-- box size="0.040 0.005 0.125"/> -->
	
        <mesh filename="file:///home/student/ROCO222_ROS/Robot_project/models/STL_files/Hand_Top.STL" scale="0.01 0.01 0.01" />
  
      </geometry>
      
        <origin rpy="0 1.57 0" xyz="0.0750 0.06 0" />
   
        <material name="green"/>
   
    </visual>
    
  </link>



  <link name="Hand_finger">
  
    <visual>
      
      <geometry>
       
         <!-- box size="0.040 0.005 0.125"/> -->
	
         <mesh filename="file:///home/student/ROCO222_ROS/Robot_project/models/STL_files/Fingery_part.STL" scale="0.01 0.01 0.01" />
    
      </geometry>
      
         <origin rpy="0 1.57 0" xyz="0.015 0.525 -0.1" />
    
         <material name="red"/>
   
    </visual>
 
  </link>




  <joint name="Hand_FB" type="fixed">
    

     <parent link="Hand_back"/>
    
     <child link="Hand_front"/>
 
     <origin xyz="0 0 0" />
  
  </joint>


 

  <joint name="Finger" type="revolute">
 
     <axis xyz="0 0 -1" />
 
     <limit effort="1000" lower="-3.14" upper="3.14" velocity="0.5" />
 
    <parent link="Hand_back"/>
 
     <child link="Hand_finger"/>
  
     <origin xyz="0.015 0.525 -0.1" />
 
  </joint>



</robot>





